Should get a better error for:

python2.7 ... import-source.py 40732d0ccc1c579ac641b0024f13e73fcdfb65d4
Traceback (most recent call last):
  File "./../simulation-tools/import-source.py", line 27, in <module>
    @easyrunto('ghdl', '-i', '--work='+args.work, '--workdir='+str(here/'objs'), args.files, echo=False, stderr=STDOUT)
  File "/home/owen/lib/python/easyrun-0.124-py2.7.egg/easyrun.py", line 24, in easyrunto
    
  File "/home/owen/lib/python/easyrun-0.124-py2.7.egg/easyrun.py", line 69, in runto
    if status != 0:
  File "/usr/lib/python2.7/subprocess.py", line 710, in __init__
    errread, errwrite)
  File "/usr/lib/python2.7/subprocess.py", line 1335, in _execute_child
    raise child_exception
OSError: [Errno 2] No such file or directory
⚠  /usr/bin/python ./../simulation-tools/import-source.py --pretend-to-be=testscangenerator-demo-1.vhd ./../../../../../../tmp/40732d0ccc1c579ac641b0024f13e73fcdfb65d4 returned 1 exit status. ⚠ 


